Workbook

Sheet Ginecologia_dados
A1: MICRORREGIÃO | B1: CÓDIGO | C1: MICRORREGIÃO | D1: MACRORREGIÃO | E1: MICRORREGIÃO | F1: MUNICÍPIO | G1: 2018 | H1: 2019 | I1: 2020 | J1: 2021 | K1: 2022 | L1: 2023 | M1: 2024
A2: PATROCÍNIO/MONTE CARMELO | B2: 310010 | C2: PATROCÍNIO/MONTE CARMELO | D2: TRIÂNGULO DO NORTE | E2: PATROCÍNIO/MONTE CARMELO | F2: ABADIA DOS DOURADOS | G2: - | H2: - | I2: - | J2: - | K2: - | L2: - | M2: -
A3: SETE LAGOAS | B3: 310020 | C3: SETE LAGOAS | D3: CENTRO | E3: SETE LAGOAS | F3: ABAETE | G3: 17 | H3: 14 | I3: 21 | J3: 33 | K3: 22 | L3: 31 | M3: 30
A4: MANHUAÇU | B4: 310030 | C4: MANHUAÇU | D4: LESTE DO SUL | E4: MANHUAÇU | F4: ABRE CAMPO | G4: 36 | H4: 111 | I4: 39 | J4: 27 | K4: 67 | L4: 77 | M4: 96
A5: PONTE NOVA | B5: 310040 | C5: PONTE NOVA | D5: LESTE DO SUL | E5: PONTE NOVA | F5: ACAIACA | G5: - | H5: - | I5: - | J5: - | K5: - | L5: - | M5: -
A6: IPATINGA | B6: 310050 | C6: IPATINGA | D6: VALE DO AÇO | E6: IPATINGA | F6: ACUCENA | G6: - | H6: - | I6: - | J6: - | K6: - | L6: - | M6: -
A7: SANTA MARIA DO SUAÇUÍ | B7: 310060 | C7: SANTA MARIA DO SUAÇUÍ | D7: LESTE | E7: SANTA MARIA DO SUAÇUÍ | F7: AGUA BOA | G7: - | H7: - | I7: - | J7: - | K7: - | L7: - | M7: -
A8: UBERABA | B8: 310070 | C8: UBERABA | D8: TRIÂNGULO DO SUL | E8: UBERABA | F8: AGUA COMPRIDA | G8: - | H8: - | I8: - | J8: - | K8: - | L8: - | M8: -
A9: CAMPO BELO | B9: 310080 | C9: CAMPO BELO | D9: OESTE | E9: CAMPO BELO | F9: AGUANIL | G9: - | H9: - | I9: - | J9: - | K9: - | L9: - | M9: -
A10: ÁGUAS FORMOSAS | B10: 310090 | C10: ÁGUAS FORMOSAS | D10: NORDESTE | E10: ÁGUAS FORMOSAS | F10: AGUAS FORMOSAS | G10: 1 | H10: 4 | I10: - | J10: 23 | K10: 54 | L10: 30 | M10: 66
A11: PEDRA AZUL | B11: 310100 | C11: PEDRA AZUL | D11: NORDESTE | E11: PEDRA AZUL | F11: AGUAS VERMELHAS | G11: - | H11: - | I11: - | J11: - | K11: - | L11: - | M11: -
A12: RESPLENDOR | B12: 310110 | C12: RESPLENDOR | D12: LESTE | E12: RESPLENDOR | F12: AIMORES | G12: 2 | H12: - | I12: 1 | J12: 1 | K12: 32 | L12: 40 | M12: 30
A13: SÃO LOURENÇO | B13: 310120 | C13: SÃO LOURENÇO | D13: SUL | E13: SÃO LOURENÇO | F13: AIURUOCA | G13: 33 | H13: 17 | I13: 25 | J13: 27 | K13: 27 | L13: 46 | M13: 52
A14: SÃO LOURENÇO | B14: 310130 | C14: SÃO LOURENÇO | D14: SUL | E14: SÃO LOURENÇO | F14: ALAGOA | G14: - | H14: - | I14: - | J14: - | K14: - | L14: - | M14: -
A15: POÇOS DE CALDAS | B15: 310140 | C15: POÇOS DE CALDAS | D15: SUL | E15: POÇOS DE CALDAS | F15: ALBERTINA | G15: - | H15: - | I15: - | J15: - | K15: - | L15: - | M15: -
A16: ALÉM PARAÍBA | B16: 310150 | C16: ALÉM PARAÍBA | D16: SUDESTE | E16: ALÉM PARAÍBA | F16: ALEM PARAIBA | G16: 9 | H16: 4 | I16: 5 | J16: 2 | K16: 8 | L16: 5 | M16: 8
A17: ALFENAS/MACHADO | B17: 310160 | C17: ALFENAS/MACHADO | D17: SUL | E17: ALFENAS/MACHADO | F17: ALFENAS | G17: 453 | H17: 436 | I17: 234 | J17: 156 | K17: 351 | L17: 452 | M17: 405
A18: BARBACENA | B18: 310163 | C18: BARBACENA | D18: CENTRO SUL | E18: BARBACENA | F18: ALFREDO VASCONCELOS | G18: - | H18: - | I18: - | J18: - | K18: - | L18: - | M18: -
A19: ALMENARA/JACINTO | B19: 310170 | C19: ALMENARA/JACINTO | D19: NORDESTE | E19: ALMENARA/JACINTO | F19: ALMENARA | G19: 63 | H19: 101 | I19: 26 | J19: 28 | K19: 87 | L19: 100 | M19: 88
A20: GOVERNADOR VALADARES | B20: 310180 | C20: GOVERNADOR VALADARES | D20: LESTE | E20: GOVERNADOR VALADARES | F20: ALPERCATA | G20: - | H20: - | I20: - | J20: - | K20: - | L20: - | M20: -
A21: PASSOS | B21: 310190 | C21: PASSOS | D21: SUL | E21: PASSOS | F21: ALPINOPOLIS | G21: - | H21: - | I21: - | J21: 1 | K21: 23 | L21: 47 | M21: 45
A22: ALFENAS/MACHADO | B22: 310200 | C22: ALFENAS/MACHADO | D22: SUL | E22: ALFENAS/MACHADO | F22: ALTEROSA | G22: 20 | H22: 25 | I22: 10 | J22: 6 | K22: 20 | L22: 36 | M22: 55
A23: MANHUAÇU | B23: 310205 | C23: MANHUAÇU | D23: LESTE DO SUL | E23: MANHUAÇU | F23: ALTO CAPARAO | G23: - | H23: - | I23: - | J23: - | K23: - | L23: - | M23: -
A24: BARBACENA | B24: 310210 | C24: BARBACENA | D24: CENTRO SUL | E24: BARBACENA | F24: ALTO RIO DOCE | G24: - | H24: - | I24: - | J24: - | K24: - | L24: - | M24: -
A25: RESPLENDOR | B25: 310220 | C25: RESPLENDOR | D25: LESTE | E25: RESPLENDOR | F25: ALVARENGA | G25: - | H25: - | I25: - | J25: - | K25: - | L25: - | M25: -
A26: PONTE NOVA | B26: 310230 | C26: PONTE NOVA | D26: LESTE DO SUL | E26: PONTE NOVA | F26: ALVINOPOLIS | G26: 18 | H26: 21 | I26: 6 | J26: 16 | K26: 36 | L26: 6 | M26: -
A27: SERRO | B27: 310240 | C27: SERRO | D27: JEQUITINHONHA | E27: SERRO | F27: ALVORADA DE MINAS | G27: - | H27: - | I27: - | J27: - | K27: - | L27: - | M27: -
A28: PONTE NOVA | B28: 310250 | C28: PONTE NOVA | D28: LESTE DO SUL | E28: PONTE NOVA | F28: AMPARO DO SERRA | G28: - | H28: - | I28: - | J28: - | K28: - | L28: - | M28: -
A29: POÇOS DE CALDAS | B29: 310260 | C29: POÇOS DE CALDAS | D29: SUL | E29: POÇOS DE CALDAS | F29: ANDRADAS | G29: 39 | H29: 31 | I29: 9 | J29: 15 | K29: 55 | L29: 41 | M29: 30
A30: PEDRA AZUL | B30: 310270 | C30: PEDRA AZUL | D30: NORDESTE | E30: PEDRA AZUL | F30: CACHOEIRA DE PAJEU | G30: - | H30: - | I30: - | J30: - | K30: - | L30: - | M30: -
A31: LIMA DUARTE | B31: 310280 | C31: LIMA DUARTE | D31: SUDESTE | E31: LIMA DUARTE | F31: ANDRELANDIA | G31: - | H31: 1 | I31: 2 | J31: 1 | K31: 6 | L31: 7 | M31: 3
A32: TEÓFILO OTONI/MALACACHETA | B32: 310285 | C32: TEÓFILO OTONI/MALACACHETA | D32: NORDESTE | E32: TEÓFILO OTONI/MALACACHETA | F32: ANGELANDIA | G32: - | H32: - | I32: - | J32: - | K32: - | L32: - | M32: -
A33: BARBACENA | B33: 310290 | C33: BARBACENA | D33: CENTRO SUL | E33: BARBACENA | F33: ANTONIO CARLOS | G33: - | H33: - | I33: - | J33: - | K33: - | L33: - | M33: -
A34: CORONEL FABRICIANO/TIMÓTEO | B34: 310300 | C34: CORONEL FABRICIANO/TIMÓTEO | D34: VALE DO AÇO | E34: CORONEL FABRICIANO/TIMÓTEO | F34: ANTONIO DIAS | G34: - | H34: - | I34: - | J34: - | K34: - | L34: - | M34: -
A35: MURIAÉ | B35: 310310 | C35: MURIAÉ | D35: SUDESTE | E35: MURIAÉ | F35: ANTONIO PRADO DE MINAS | G35: - | H35: - | I35: - | J35: - | K35: - | L35: - | M35: -
A36: SETE LAGOAS | B36: 310320 | C36: SETE LAGOAS | D36: CENTRO | E36: SETE LAGOAS | F36: ARACAI | G36: - | H36: - | I36: - | J36: - | K36: - | L36: - | M36: -
A37: SANTOS DUMONT | B37: 310330 | C37: SANTOS DUMONT | D37: SUDESTE | E37: SANTOS DUMONT | F37: ARACITABA | G37: - | H37: - | I37: - | J37: - | K37: - | L37: - | M37: -
A38: ARAÇUAÍ | B38: 310340 | C38: ARAÇUAÍ | D38: JEQUITINHONHA | E38: ARAÇUAÍ | F38: ARACUAI | G38: 28 | H38: 83 | I38: 45 | J38: 20 | K38: 101 | L38: 135 | M38: 132
A39: UBERLÂNDIA/ARAGUARI | B39: 310350 | C39: UBERLÂNDIA/ARAGUARI | D39: TRIÂNGULO DO NORTE | E39: UBERLÂNDIA/ARAGUARI | F39: ARAGUARI | G39: 107 | H39: 139 | I39: 34 | J39: 17 | K39: 86 | L39: 256 | M39: 466
A40: LIMA DUARTE | B40: 310360 | C40: LIMA DUARTE | D40: SUDESTE | E40: LIMA DUARTE | F40: ARANTINA | G40: - | H40: - | I40: - | J40: - | K40: - | L40: - | M40: -
...

Sheet População
A1: codigo | B1: municipio | C1: macro | D1: micro | E1: População_residente
A2: 310010 | B2: ABADIA DOS DOURADOS | C2: =VLOOKUP(População!A2,Ginecologia_dados!B:E,3,FALSE) -> TRIÂNGULO DO NORTE | D2: =VLOOKUP(A2,Ginecologia_dados!B:C,2,FALSE) -> PATROCÍNIO/MONTE CARMELO | E2: 3224
A3: 310020 | B3: ABAETE | C3: =VLOOKUP(População!A3,Ginecologia_dados!B:E,3,FALSE) -> CENTRO | D3: =VLOOKUP(A3,Ginecologia_dados!B:C,2,FALSE) -> SETE LAGOAS | E3: 11680
A4: 310030 | B4: ABRE CAMPO | C4: =VLOOKUP(População!A4,Ginecologia_dados!B:E,3,FALSE) -> LESTE DO SUL | D4: =VLOOKUP(A4,Ginecologia_dados!B:C,2,FALSE) -> MANHUAÇU | E4: 6954
A5: 310040 | B5: ACAIACA | C5: =VLOOKUP(População!A5,Ginecologia_dados!B:E,3,FALSE) -> LESTE DO SUL | D5: =VLOOKUP(A5,Ginecologia_dados!B:C,2,FALSE) -> PONTE NOVA | E5: 2057
A6: 310050 | B6: ACUCENA | C6: =VLOOKUP(População!A6,Ginecologia_dados!B:E,3,FALSE) -> VALE DO AÇO | D6: =VLOOKUP(A6,Ginecologia_dados!B:C,2,FALSE) -> IPATINGA | E6: 4640
A7: 310060 | B7: AGUA BOA | C7: =VLOOKUP(População!A7,Ginecologia_dados!B:E,3,FALSE) -> LESTE | D7: =VLOOKUP(A7,Ginecologia_dados!B:C,2,FALSE) -> SANTA MARIA DO SUAÇUÍ | E7: 6694
A8: 310070 | B8: AGUA COMPRIDA | C8: =VLOOKUP(População!A8,Ginecologia_dados!B:E,3,FALSE) -> TRIÂNGULO DO SUL | D8: =VLOOKUP(A8,Ginecologia_dados!B:C,2,FALSE) -> UBERABA | E8: 1031
A9: 310080 | B9: AGUANIL | C9: =VLOOKUP(População!A9,Ginecologia_dados!B:E,3,FALSE) -> OESTE | D9: =VLOOKUP(A9,Ginecologia_dados!B:C,2,FALSE) -> CAMPO BELO | E9: 2193
A10: 310090 | B10: AGUAS FORMOSAS | C10: =VLOOKUP(População!A10,Ginecologia_dados!B:E,3,FALSE) -> NORDESTE | D10: =VLOOKUP(A10,Ginecologia_dados!B:C,2,FALSE) -> ÁGUAS FORMOSAS | E10: 9376
A11: 310100 | B11: AGUAS VERMELHAS | C11: =VLOOKUP(População!A11,Ginecologia_dados!B:E,3,FALSE) -> NORDESTE | D11: =VLOOKUP(A11,Ginecologia_dados!B:C,2,FALSE) -> PEDRA AZUL | E11: 6829
A12: 310110 | B12: AIMORES | C12: =VLOOKUP(População!A12,Ginecologia_dados!B:E,3,FALSE) -> LESTE | D12: =VLOOKUP(A12,Ginecologia_dados!B:C,2,FALSE) -> RESPLENDOR | E12: 13152
A13: 310120 | B13: AIURUOCA | C13: =VLOOKUP(População!A13,Ginecologia_dados!B:E,3,FALSE) -> SUL | D13: =VLOOKUP(A13,Ginecologia_dados!B:C,2,FALSE) -> SÃO LOURENÇO | E13: 3110
... A854: 317220 | B854: WENCESLAU BRAZ | C854: =VLOOKUP(População!A854,Ginecologia_dados!B:E,3,FALSE) -> SUL | D854: =VLOOKUP(A854,Ginecologia_dados!B:C,2,FALSE) -> ITAJUBÁ | E854: 1224

Sheet Dados_Macrorregião
A1: MACRORREGIÕES | B1: POPULAÇÃO FEMININA | C1: 2018 | D1: 2019 | E1: 2020 | F1: 2021 | G1: 2022 | H1: 2023 | I1: 2024
A2: CENTRO | B2: 3377209 | C2: 8679 | D2: 8276 | E2: 4178 | F2: 4354 | G2: 10881 | H2: 12553 | I2: 12109
A3: CENTRO SUL | B3: 398051 | C3: 746 | D3: 861 | E3: 438 | F3: 450 | G3: 1018 | H3: 897 | I3: 1225
A4: JEQUITINHONHA | B4: 199599 | C4: 603 | D4: 694 | E4: 291 | F4: 315 | G4: 830 | H4: 1209 | I4: 1365
A5: LESTE | B5: 343037 | C5: 843 | D5: 684 | E5: 371 | F5: 364 | G5: 856 | H5: 1313 | I5: 1638
A6: LESTE DO SUL | B6: 352121 | C6: 1119 | D6: 1057 | E6: 640 | F6: 707 | G6: 996 | H6: 996 | I6: 1093
A7: NORDESTE | B7: 406281 | C7: 1070 | D7: 1104 | E7: 422 | F7: 587 | G7: 1560 | H7: 1949 | I7: 2711
A8: NOROESTE | B8: 354717 | C8: 1084 | D8: 1087 | E8: 499 | F8: 443 | G8: 1216 | H8: 1542 | I8: 1454
A9: NORTE | B9: 827805 | C9: 2614 | D9: 2613 | E9: 1077 | F9: 1312 | G9: 3277 | H9: 5926 | I9: 5467
A10: OESTE | B10: 647918 | C10: 1279 | D10: 1192 | E10: 708 | F10: 736 | G10: 1768 | H10: 2103 | I10: 2429
A11: SUDESTE | B11: 849097 | C11: 1873 | D11: 1634 | E11: 776 | F11: 996 | G11: 1639 | H11: 2032 | I11: 2065
A12: SUL | B12: 1411689 | C12: 2760 | D12: 2663 | E12: 1610 | F12: 1512 | G12: 2814 | H12: 4026 | I12: 4513
A13: TRIÂNGULO DO NORTE | B13: 668990 | C13: 2070 | D13: 2206 | E13: 1088 | F13: 1196 | G13: 1694 | H13: 2212 | I13: 3036
... A15: VALE DO AÇO | B15: 414970 | C15: 656 | D15: 493 | E15: 298 | F15: 364 | G15: 773 | H15: 1193 | I15: 1378
A16: Total Geral | B16: =SUM(B2:B15) -> 10644318 | C16: 26177 | D16: 25330 | E16: 12789 | F16: 13649 | G16: 29880 | H16: 38799 | I16: 41440

Sheet Variação % anual
A1: VARIAÇÃO PERCENTUAL ANUAL (VALOR NO ANO ATUAL - VALOR NO ANO ANTERIOR)/VALOR NO ANO ANTERIOR*100
A2: MACRORREGIÕES | B2: 2018 | C2: 2019 | D2: VAR (18-19) | E2: 2020 | F2: VAR (19-20) | G2: 2021 | H2: VAR (20-21) | I2: 2022 | J2: VAR (21-22) | K2: 2023 | L2: VAR (22-23) | M2: 2024 | N2: VAR (23-24)
A3: CENTRO | B3: 8679 | C3: 8276 | D3: =(C3-B3)/B3*100 -> -4.6433921 | E3: 4178 | F3: =(E3-C3)/C3*100 -> -49.516675 | G3: 4354 | H3: =(G3-E3)/E3*100 -> 4.2125419 | I3: 10881 | J3: =(I3-G3)/G3*100 -> 149.90813 | K3: 12553 | L3: =(K3-I3)/I3*100 -> 15.366235 | M3: 12109 | N3: =(M3-K3)/K3*100 -> -3.5370031
A4: CENTRO SUL | B4: 746 | C4: 861 | D4: =(C4-B4)/B4*100 -> 15.41555 | E4: 438 | F4: =(E4-C4)/C4*100 -> -49.12892 | G4: 450 | H4: =(G4-E4)/E4*100 -> 2.739726 | I4: 1018 | J4: =(I4-G4)/G4*100 -> 126.22222 | K4: 897 | L4: =(K4-I4)/I4*100 -> -11.886051 | M4: 1225 | N4: =(M4-K4)/K4*100 -> 36.566332
A5: JEQUITINHONHA | B5: 603 | C5: 694 | D5: =(C5-B5)/B5*100 -> 15.091211 | E5: 291 | F5: =(E5-C5)/C5*100 -> -58.069164 | G5: 315 | H5: =(G5-E5)/E5*100 -> 8.2474227 | I5: 830 | J5: =(I5-G5)/G5*100 -> 163.49206 | K5: 1209 | L5: =(K5-I5)/I5*100 -> 45.662651 | M5: 1365 | N5: =(M5-K5)/K5*100 -> 12.903226
A6: LESTE | B6: 843 | C6: 684 | D6: =(C6-B6)/B6*100 -> -18.86121 | E6: 371 | F6: =(E6-C6)/C6*100 -> -45.760234 | G6: 364 | H6: =(G6-E6)/E6*100 -> -1.8867925 | I6: 856 | J6: =(I6-G6)/G6*100 -> 135.16484 | K6: 1313 | L6: =(K6-I6)/I6*100 -> 53.38785 | M6: 1638 | N6: =(M6-K6)/K6*100 -> 24.752475
A7: LESTE DO SUL | B7: 1119 | C7: 1057 | D7: =(C7-B7)/B7*100 -> -5.5406613 | E7: 640 | F7: =(E7-C7)/C7*100 -> -39.451277 | G7: 707 | H7: =(G7-E7)/E7*100 -> 10.46875 | I7: 996 | J7: =(I7-G7)/G7*100 -> 40.876945 | K7: 996 | L7: =(K7-I7)/I7*100 -> 0 | M7: 1093 | N7: =(M7-K7)/K7*100 -> 9.7389558
A8: NORDESTE | B8: 1070 | C8: 1104 | D8: =(C8-B8)/B8*100 -> 3.1775701 | E8: 422 | F8: =(E8-C8)/C8*100 -> -61.775362 | G8: 587 | H8: =(G8-E8)/E8*100 -> 39.099526 | I8: 1560 | J8: =(I8-G8)/G8*100 -> 165.75809 | K8: 1949 | L8: =(K8-I8)/I8*100 -> 24.935897 | M8: 2711 | N8: =(M8-K8)/K8*100 -> 39.096973
A9: NOROESTE | B9: 1084 | C9: 1087 | D9: =(C9-B9)/B9*100 -> 0.27675277 | E9: 499 | F9: =(E9-C9)/C9*100 -> -54.093836 | G9: 443 | H9: =(G9-E9)/E9*100 -> -11.222445 | I9: 1216 | J9: =(I9-G9)/G9*100 -> 174.4921 | K9: 1542 | L9: =(K9-I9)/I9*100 -> 26.809211 | M9: 1454 | N9: =(M9-K9)/K9*100 -> -5.7068742
A10: NORTE | B10: 2614 | C10: 2613 | D10: =(C10-B10)/B10*100 -> -0.038255547 | E10: 1077 | F10: =(E10-C10)/C10*100 -> -58.783008 | G10: 1312 | H10: =(G10-E10)/E10*100 -> 21.81987 | I10: 3277 | J10: =(I10-G10)/G10*100 -> 149.77134 | K10: 5926 | L10: =(K10-I10)/I10*100 -> 80.836131 | M10: 5467 | N10: =(M10-K10)/K10*100 -> -7.7455282
A11: OESTE | B11: 1279 | C11: 1192 | D11: =(C11-B11)/B11*100 -> -6.8021892 | E11: 708 | F11: =(E11-C11)/C11*100 -> -40.604027 | G11: 736 | H11: =(G11-E11)/E11*100 -> 3.9548023 | I11: 1768 | J11: =(I11-G11)/G11*100 -> 140.21739 | K11: 2103 | L11: =(K11-I11)/I11*100 -> 18.947964 | M11: 2429 | N11: =(M11-K11)/K11*100 -> 15.501664
A12: SUDESTE | B12: 1873 | C12: 1634 | D12: =(C12-B12)/B12*100 -> -12.760278 | E12: 776 | F12: =(E12-C12)/C12*100 -> -52.50918 | G12: 996 | H12: =(G12-E12)/E12*100 -> 28.350515 | I12: 1639 | J12: =(I12-G12)/G12*100 -> 64.558233 | K12: 2032 | L12: =(K12-I12)/I12*100 -> 23.978035 | M12: 2065 | N12: =(M12-K12)/K12*100 -> 1.6240157
A13: SUL | B13: 2760 | C13: 2663 | D13: =(C13-B13)/B13*100 -> -3.5144928 | E13: 1610 | F13: =(E13-C13)/C13*100 -> -39.54187 | G13: 1512 | H13: =(G13-E13)/E13*100 -> -6.0869565 | I13: 2814 | J13: =(I13-G13)/G13*100 -> 86.111111 | K13: 4026 | L13: =(K13-I13)/I13*100 -> 43.070362 | M13: 4513 | N13: =(M13-K13)/K13*100 -> 12.096374
A14: TRIÂNGULO DO NORTE | B14: 2070 | C14: 2206 | D14: =(C14-B14)/B14*100 -> 6.5700483 | E14: 1088 | F14: =(E14-C14)/C14*100 -> -50.679964 | G14: 1196 | H14: =(G14-E14)/E14*100 -> 9.9264706 | I14: 1694 | J14: =(I14-G14)/G14*100 -> 41.638796 | K14: 2212 | L14: =(K14-I14)/I14*100 -> 30.578512 | M14: 3036 | N14: =(M14-K14)/K14*100 -> 37.251356
... A17: Total Geral | B17: 26177 | C17: 25330 | D17: =(C17-B17)/B17*100 -> -3.2356649 | E17: 12789 | F17: =(E17-C17)/C17*100 -> -49.510462 | G17: 13649 | H17: =(G17-E17)/E17*100 -> 6.7245289 | I17: 29880 | J17: =(I17-G17)/G17*100 -> 118.91714 | K17: 38799 | L17: =(K17-I17)/I17*100 -> 29.849398 | M17: 41440 | N17: =(M17-K17)/K17*100 -> 6.8068765

Sheet Variação exceto pandemia
A1: VARIAÇÃO PERCENTUAL 2019-2022 (PARA DESCONSIDERAR A REDUÇÃO CAUSADA POR SUSPENSÃO DE SERVIÇOS ELETIVOS NA PANDEMIA)
A2: MACRORREGIÕES | B2: 2019 | C2: 2022 | D2: VAR (19-22)
A3: CENTRO | B3: 8276 | C3: 10881 | D3: =(C3-B3)/B3*100 -> 31.476559
A4: CENTRO SUL | B4: 861 | C4: 1018 | D4: =(C4-B4)/B4*100 -> 18.234611
A5: JEQUITINHONHA | B5: 694 | C5: 830 | D5: =(C5-B5)/B5*100 -> 19.596542
A6: LESTE | B6: 684 | C6: 856 | D6: =(C6-B6)/B6*100 -> 25.146199
A7: LESTE DO SUL | B7: 1057 | C7: 996 | D7: =(C7-B7)/B7*100 -> -5.7710501
A8: NORDESTE | B8: 1104 | C8: 1560 | D8: =(C8-B8)/B8*100 -> 41.304348
A9: NOROESTE | B9: 1087 | C9: 1216 | D9: =(C9-B9)/B9*100 -> 11.867525
A10: NORTE | B10: 2613 | C10: 3277 | D10: =(C10-B10)/B10*100 -> 25.411405
A11: OESTE | B11: 1192 | C11: 1768 | D11: =(C11-B11)/B11*100 -> 48.322148
A12: SUDESTE | B12: 1634 | C12: 1639 | D12: =(C12-B12)/B12*100 -> 0.30599755
A13: SUL | B13: 2663 | C13: 2814 | D13: =(C13-B13)/B13*100 -> 5.6702967
A14: TRIÂNGULO DO NORTE | B14: 2206 | C14: 1694 | D14: =(C14-B14)/B14*100 -> -23.209429
... A17: Total Geral | B17: 25330 | C17: 29880 | D17: =(C17-B17)/B17*100 -> 17.96289

Sheet Cirurgias por 100.000 hab
A1: CIRURGIAS POR 100 MIL HABITANTES (CIRURGIAS/POPULAÇÃO*100000)
A2: MACRORREGIÕES | B2: POPULAÇÃO FEMININA | C2: 2018 | D2: 2019 | E2: 2020 | F2: 2021 | G2: 2022 | H2: 2023 | I2: 2024 | J2: 22-19 | K2: 23-19 | L2: 24-19
A3: CENTRO | B3: 3377209 | C3: 256.98735 | D3: 245.05442 | E3: 123.71162 | F3: 128.92302 | G3: 322.18912 | H3: 371.69746 | I3: 358.55051 | J3: =G3-D3 -> 77.134699 | K3: =H3-D3 -> 126.64304 | L3: =I3-D3 -> 113.49609
A4: CENTRO SUL | B4: 398051 | C4: 187.41317 | D4: 216.30394 | E4: 110.03615 | F4: 113.05084 | G4: 255.74612 | H4: 225.34801 | I4: 307.74951 | J4: =G4-D4 -> 39.442182 | K4: =H4-D4 -> 9.0440672 | L4: =I4-D4 -> 91.445569
A5: JEQUITINHONHA | B5: 199599 | C5: 302.10572 | D5: 347.69713 | E5: 145.79231 | F5: 157.81642 | G5: 415.83375 | H5: 605.71446 | I5: 683.87116 | J5: =G5-D5 -> 68.136614 | K5: =H5-D5 -> 258.01732 | L5: =I5-D5 -> 336.17403
A6: LESTE | B6: 343037 | C6: 245.74609 | D6: 199.3954 | E6: 108.1516 | F6: 106.111 | G6: 249.53576 | H6: 382.75755 | I6: 477.49951 | J6: =G6-D6 -> 50.140364 | K6: =H6-D6 -> 183.36214 | L6: =I6-D6 -> 278.10411
A7: LESTE DO SUL | B7: 352121 | C7: 317.78849 | D7: 300.1809 | E7: 181.7557 | F7: 200.78325 | G7: 282.85731 | H7: 282.85731 | I7: 310.40466 | J7: =G7-D7 -> -17.32359 | K7: =H7-D7 -> -17.32359 | L7: =I7-D7 -> 10.223758
A8: NORDESTE | B8: 406281 | C8: 263.36452 | D8: 271.73311 | E8: 103.869 | F8: 144.48128 | G8: 383.9707 | H8: 479.71724 | I8: 667.27216 | J8: =G8-D8 -> 112.23759 | K8: =H8-D8 -> 207.98413 | L8: =I8-D8 -> 395.53905
A9: NOROESTE | B9: 354717 | C9: 305.59573 | D9: 306.44147 | E9: 140.67552 | F9: 124.88829 | G9: 342.80849 | H9: 434.71274 | I9: 409.90423 | J9: =G9-D9 -> 36.367019 | K9: =H9-D9 -> 128.27127 | L9: =I9-D9 -> 103.46276
A10: NORTE | B10: 827805 | C10: 315.77485 | D10: 315.65405 | E10: 130.1031 | F10: 158.49143 | G10: 395.86618 | H10: 715.86908 | I10: 660.42123 | J10: =G10-D10 -> 80.212127 | K10: =H10-D10 -> 400.21503 | L10: =I10-D10 -> 344.76719
A11: OESTE | B11: 647918 | C11: 197.40152 | D11: 183.9739 | E11: 109.27309 | F11: 113.59462 | G11: 272.87404 | H11: 324.57811 | I11: 374.89312 | J11: =G11-D11 -> 88.900139 | K11: =H11-D11 -> 140.60421 | L11: =I11-D11 -> 190.91922
A12: SUDESTE | B12: 849097 | C12: 220.58728 | D12: 192.43973 | E12: 91.391207 | F12: 117.30109 | G12: 193.02859 | H12: 239.31306 | I12: 243.19954 | J12: =G12-D12 -> 0.58886087 | K12: =H12-D12 -> 46.873325 | L12: =I12-D12 -> 50.759807
A13: SUL | B13: 1411689 | C13: 195.51048 | D13: 188.63928 | E13: 114.04778 | F13: 107.10574 | G13: 199.33569 | H13: 285.19029 | I13: 319.68798 | J13: =G13-D13 -> 10.696407 | K13: =H13-D13 -> 96.551011 | L13: =I13-D13 -> 131.04869
A14: TRIÂNGULO DO NORTE | B14: 668990 | C14: 309.42167 | D14: 329.75082 | E14: 162.63322 | F14: 178.77696 | G14: 253.21754 | H14: 330.64769 | I14: 453.81844 | J14: =G14-D14 -> -76.533282 | K14: =H14-D14 -> 0.89687439 | L14: =I14-D14 -> 124.06762
... A16: VALE DO AÇO | B16: 414970 | C16: 158.08372 | D16: 118.80377 | E16: 71.81242 | F16: 87.717184 | G16: 186.27853 | H16: 287.49066 | I16: 332.0722 | J16: =G16-D16 -> 67.474757 | K16: =H16-D16 -> 168.68689 | L16: =I16-D16 -> 213.26843
A17: Total Geral | B17: =SUM(B3:B16) -> 10644318 | C17: 245.92463 | D17: 237.96734 | E17: 120.14861 | F17: 128.22804 | G17: 280.71315 | H17: 364.50433 | I17: 389.31569 | J17: =G17-D17 -> 42.74581 | K17: =H17-D17 -> 126.53699 | L17: =I17-D17 -> 151.34835

Sheet Análise_Estadual
A1: ANO_ANÁLISE | B1: TOTAL_ESTADUAL | C1: VARIAÇÃO PERCENTUAL ANUAL
A2: 2018 | B2: 26177 | C2: SEM ANO BASE PARA COMPARAÇÃO
A3: 2019 | B3: 25330 | C3: =(B3-B2)/B2*100 -> -3.2356649
A4: 2020 | B4: 12789 | C4: =(B4-B3)/B3*100 -> -49.510462
A5: 2021 | B5: 13649 | C5: =(B5-B4)/B4*100 -> 6.7245289
A6: 2022 | B6: 29880 | C6: =(B6-B5)/B5*100 -> 118.91714
A7: 2023 | B7: 38799 | C7: =(B7-B6)/B6*100 -> 29.849398
A8: 2024 | B8: 41440 | C8: =(B8-B7)/B7*100 -> 6.8068765
